Workbook

Sheet Sheet7

Sheet Cleaned Data
A1: Column1 | B1: Column2 | C1: Column3 | D1: Column4 | E1: Column5 | F1: Column6 | G1: Column7 | H1: Column8 | I1: Column9 | J1: Column10 | K1: Column11
A2: Order Id | B2: Date | C2: Product | D2: Category | E2: Quantity | F2: Unit Price | G2: Sales Amount | H2: Payment Method | I2: Customer Type | J2: City | K2: Formatted Date
A3: FM0001 | B3: 46051 | C3: Coffee | D3: Beverages | E3: 1 | F3: 4500 | G3: 4500 | H3: Transfer | I3: Regular | J3: Ibadan | K3: =TEXT($B3,"mmmm") -> January
A4: FM0002 | B4: 46049 | C4: Bread | D4: Bakery | E4: 6 | F4: 1800 | G4: 10800 | H4: Cash | I4: New | J4: Lagos | K4: =TEXT($B4,"mmmm") -> January
A5: FM0003 | B5: 46046 | C5: Rice 5kg | D5: Groceries | E5: 2 | F5: 8500 | G5: 17000 | H5: Card | I5: Regular | J5: Ibadan | K5: =TEXT($B5,"mmmm") -> January
A6: FM0004 | B6: 46162 | C6: Laundry Detergent | D6: Household | E6: 4 | F6: 3800 | G6: 15200 | H6: Card | I6: New | J6: Osogbo | K6: =TEXT($B6,"mmmm") -> May
A7: FM0005 | B7: 46063 | C7: Rice 5kg | D7: Groceries | E7: 6 | F7: 8500 | G7: 51000 | H7: POS | I7: New | J7: Osogbo | K7: =TEXT($B7,"mmmm") -> February
A8: FM0006 | B8: 46078 | C8: Bread | D8: Bakery | E8: 3 | F8: 1800 | G8: 5400 | H8: Cash | I8: Regular | J8: Ife | K8: =TEXT($B8,"mmmm") -> February
A9: FM0007 | B9: 46114 | C9: Vegetable Oil 1L | D9: Groceries | E9: 3 | F9: 3200 | G9: 9600 | H9: Transfer | I9: Regular | J9: Ife | K9: =TEXT($B9,"mmmm") -> April
A10: FM0008 | B10: 46054 | C10: Soft Drink | D10: Beverages | E10: 4 | F10: 1000 | G10: 4000 | H10: Cash | I10: New | J10: Osogbo | K10: =TEXT($B10,"mmmm") -> February
A11: FM0009 | B11: 46072 | C11: Bottled Water | D11: Beverages | E11: 6 | F11: 500 | G11: 3000 | H11: Cash | I11: Regular | J11: Ibadan | K11: =TEXT($B11,"mmmm") -> February
A12: FM0010 | B12: 46043 | C12: Eggs (12) | D12: Dairy | E12: 2 | F12: 4200 | G12: 8400 | H12: Cash | I12: New | J12: Osogbo | K12: =TEXT($B12,"mmmm") -> January
A13: FM0011 | B13: 46116 | C13: Potato Chips | D13: Snacks | E13: 2 | F13: 1800 | G13: 3600 | H13: Transfer | I13: New | J13: Ibadan | K13: =TEXT($B13,"mmmm") -> April
A14: FM0012 | B14: 46091 | C14: Coffee | D14: Beverages | E14: 6 | F14: 4500 | G14: 27000 | H14: Cash | I14: Regular | J14: Ibadan | K14: =TEXT($B14,"mmmm") -> March
... A101: FM0099 | B101: 46040 | C101: Coffee | D101: Beverages | E101: 6 | F101: 4500 | G101: 27000 | H101: Cash | I101: Regular | J101: Ibadan | K101: =TEXT($B101,"mmmm") -> January

Sheet Analysis
A1: Column1 | B1: Column2 | C1: Column3 | D1: Column4 | E1: Column5
B2: Data Analysis
A3: Overall Performance | C3: Location Analysis
A4: Total Revenue | B4: =SUM('Cleaned Data'!G3:G101) -> 1013900 | C4: City with the highest revenue | D4: =INDEX(C7:C10,MATCH(MAX(D7:D10),D7:D10,0)) -> Lagos
A5: Total Quantity Sold | B5: =SUM('Cleaned Data'!E3:E101) -> 320 | C5: City with the lowest revenue | D5: =INDEX(C8:C11,MATCH(MIN(D8:D10),D8:D10,0)) -> Ife
A6: Average Sales Amount | B6: =AVERAGE('Cleaned Data'!G3:G101) -> 10241.414 | C6: Revenue generated by each city;
A7: Highest Transaction | B7: =MAX('Cleaned Data'!G3:G101) -> 51000 | C7: Lagos | D7: =SUMIFS('Cleaned Data'!$G$3:$G$101,'Cleaned Data'!$J$3:$J$101,$C7) -> 308500
A8: Lowest Transaction | B8: =MIN('Cleaned Data'!G3:G101) -> 1000 | C8: Ife | D8: =SUMIFS('Cleaned Data'!$G$3:$G$101,'Cleaned Data'!$J$3:$J$101,$C8) -> 202100
A9: Number of Transaction | B9: =COUNTA('Cleaned Data'!A3:A101) -> 99 | C9: Osogbo | D9: =SUMIFS('Cleaned Data'!$G$3:$G$101,'Cleaned Data'!$J$3:$J$101,$C9) -> 209400
C10: Ibadan | D10: =SUMIFS('Cleaned Data'!$G$3:$G$101,'Cleaned Data'!$J$3:$J$101,$C10) -> 293900
A12: Product Performance | C12: Payment Analysis
A13: Product with the highest total revenue | B13: =INDEX(Sheet9!$A$3:$A$14,MATCH(MAX(Sheet9!B3:B14),Sheet9!$B$3:$B$14,0)) -> Rice 5kg | C13: Most frequently used payment method | D13: =INDEX(C15:C18,MATCH(MAX(D15:D18),D15:D18)) -> Cash
A14: Product with the lowest total revenue | B14: =INDEX(Sheet9!$A$3:$A$14,MATCH(MIN(Sheet9!$B$3:$B$14),Sheet9!$B$3:$B$14,0)) -> Bottled Water | C14: Number of transactions for each payment method;
A15: Product with the highest quantity sold | B15: =INDEX(Sheet9!$A$3:$A$14,MATCH(MAX(Sheet9!$D$3:$D$14),Sheet9!$D$3:$D$14,0)) -> Coffee | C15: Transfer | D15: =COUNTIFS('Cleaned Data'!H:H,"Transfer") -> 26
A16: Product with the lowest quantity sold | B16: =INDEX(Sheet9!$A$3:$A$14,MATCH(MIN(Sheet9!$D$3:$D$14),Sheet9!$D$3:$D$14,0)) -> Milk 1L | C16: Cash | D16: =COUNTIFS('Cleaned Data'!H:H,"Cash") -> 29
C17: Card | D17: =COUNTIFS('Cleaned Data'!H:H,"Card") -> 20
A18: Category Performance | C18: POS | D18: =COUNTIFS('Cleaned Data'!H:H,"POS") -> 24
A19: Category with the highest revenue | B19: =INDEX($A$22:$A$27,MATCH(MAX($B$22:$B$27),$B$22:$B$27,0)) -> Groceries
A20: Category with the lowest revenue | B20: =INDEX($A$22:$A$27,MATCH(MIN($B$22:$B$27),$B$22:$B$27,0)) -> Bakery
A21: Revenue generated by each category;
A22: Beverages | B22: =SUMIFS('Cleaned Data'!G$3:$G$101,'Cleaned Data'!$D$3:$D$101,$A22) -> 273500
A23: Bakery | B23: =SUMIFS('Cleaned Data'!G$3:$G$101,'Cleaned Data'!$D$3:$D$101,$A23) -> 57600
A24: Groceries | B24: =SUMIFS('Cleaned Data'!G$3:$G$101,'Cleaned Data'!$D$3:$D$101,$A24) -> 363600
A25: Snacks | B25: =SUMIFS('Cleaned Data'!G$3:$G$101,'Cleaned Data'!$D$3:$D$101,$A25) -> 71400
A26: Dairy | B26: =SUMIFS('Cleaned Data'!$G$3:$G$101,'Cleaned Data'!$D$3:$D$101,A26) -> 160400
A27: Household | B27: =SUMIFS('Cleaned Data'!G$3:$G$101,'Cleaned Data'!$D$3:$D$101,$A27) -> 87400
A29: Customer Analysis
A30: Revenue from Regular customers | B30: =SUMIFS('Cleaned Data'!$G$3:$G$101,'Cleaned Data'!$I$3:$I$101,"Regular") -> 527200
A31: Revenue from New customers | B31: =SUMIFS('Cleaned Data'!$G$3:$G$101,'Cleaned Data'!$I$3:$I$101,"New") -> 486700
A32: Which Customer type generated most revenue? | B32: =MAX(B30:B31) -> 527200

Sheet Monthly Analysis
A1: Monthly Revenue | B1: Column1 | C1: Column2 | D1: Column3 | E1: Column4
A2: Revenue for each month
A3: January | B3: =SUMIFS('Cleaned Data'!G:G,'Cleaned Data'!K:K,$A3) -> 289600
A4: February | B4: =SUMIFS('Cleaned Data'!G:G,'Cleaned Data'!K:K,$A4) -> 170700
A5: March | B5: =SUMIFS('Cleaned Data'!G:G,'Cleaned Data'!K:K,$A5) -> 159200
A6: April | B6: =SUMIFS('Cleaned Data'!G:G,'Cleaned Data'!K:K,$A6) -> 224500
A7: May | B7: =SUMIFS('Cleaned Data'!G:G,'Cleaned Data'!K:K,$A7) -> 169900
A9: Quantity sold each month | E9: Highest-revenue month
A10: =$A3 -> January | B10: =SUMIFS('Cleaned Data'!E:E,'Cleaned Data'!K:K,$A3) -> 67 | E10: =INDEX(A3:A7,MATCH(MAX(B3:B7),B3:B7,0)) -> January
A11: =$A4 -> February | B11: =SUMIFS('Cleaned Data'!E:E,'Cleaned Data'!K:K,$A4) -> 62 | E11: Lowest-revenue month
A12: =$A5 -> March | B12: =SUMIFS('Cleaned Data'!E:E,'Cleaned Data'!K:K,$A5) -> 56 | E12: =INDEX(A3:A7,MATCH(MIN(B3:B7),B3:B7,0)) -> March
A13: =$A6 -> April | B13: =SUMIFS('Cleaned Data'!E:E,'Cleaned Data'!K:K,$A6) -> 85
A14: =$A7 -> May | B14: =SUMIFS('Cleaned Data'!E:E,'Cleaned Data'!K:K,$A7) -> 50
A16: Number of transactions each month
A17: =$A3 -> January | B17: =COUNTIFS('Cleaned Data'!K:K,$A17) -> 16
A18: =$A4 -> February | B18: =COUNTIFS('Cleaned Data'!K:K,$A18) -> 19
A19: =$A5 -> March | B19: =COUNTIFS('Cleaned Data'!K:K,$A19) -> 19
A20: =$A6 -> April | B20: =COUNTIFS('Cleaned Data'!K:K,$A20) -> 28
A21: =$A7 -> May | B21: =COUNTIFS('Cleaned Data'!K:K,$A21) -> 17

Sheet Sheet5

Sheet Sheet6

Sheet Sheet4
A1: Monthly Revenue | N1: Revenue by Product
A2: Row Labels | B2: Count of Column7 | E2: Row Labels | F2: Sum of Sum of Column7
A3: January | B3: 16 | E3: Biscuits | F3: 40800
A4: February | B4: 19 | E4: Bottled Water | F4: 9000 | H4: Values
A5: March | B5: 19 | E5: Bread | F5: 57600 | G5: Row Labels | H5: Sum of 1 | I5: Count of Ibadan
A6: April | B6: 28 | E6: Coffee | F6: 229500 | G6: Biscuits | H6: 34 | I6: 11
A7: May | B7: 17 | E7: Eggs (12) | F7: 96600 | G7: Bottled Water | H7: 18 | I7: 4
A8: Grand Total | B8: 99 | E8: Grand Total | F8: 1013900 | G8: Bread | H8: 32 | I8: 11
E9: Laundry Detergent | F9: 87400 | G9: Coffee | H9: 50 | I9: 13
E10: Milk 1L | F10: 30800 | G10: Eggs (12) | H10: 23 | I10: 8
E11: Potato Chips | F11: 30600 | G11: Laundry Detergent | H11: 23 | I11: 6
E12: Rice 5kg | F12: 306000 | G12: Milk 1L | H12: 11 | I12: 5
E13: Soft Drink | F13: 35000 | G13: Potato Chips | H13: 17 | I13: 7
A14: Revenue by Category | E14: Vegetable Oil 1L | F14: 57600 | G14: Rice 5kg | H14: 36 | I14: 11
A15: Row Labels | B15: Count of Column7 | E15: Yoghurt | F15: 33000 | G15: Soft Drink | H15: 35 | I15: 10
A16: Bakery | B16: 11 | E16: Grand Total | F16: 2027800 | G16: Vegetable Oil 1L | H16: 18 | I16: 5
A17: Beverages | B17: 28 | G17: Yoghurt | H17: 22 | I17: 7
A18: Dairy | B18: 20 | E18: Row Labels | F18: Sum of Sum of Column7 | G18: Grand Total | H18: 319 | I18: 98
A19: Groceries | B19: 16 | E19: Biscuits | F19: 40800
A20: Household | B20: 6 | E20: Bottled Water | F20: 9000 | N20: Revenue by City
A21: Snacks | B21: 18 | E21: Bread | F21: 57600 | N21: Row Labels | O21: Sum of Column7
A22: Grand Total | B22: 99 | E22: Coffee | F22: 229500 | N22: Ibadan | O22: 293900
E23: Eggs (12) | F23: 96600 | N23: Ife | O23: 202100
E24: Laundry Detergent | F24: 87400 | N24: Lagos | O24: 308500
E25: Milk 1L | F25: 30800 | N25: Osogbo | O25: 209400
E26: Potato Chips | F26: 30600 | N26: Grand Total | O26: 1013900
E27: Rice 5kg | F27: 306000
E28: Soft Drink | F28: 35000
E29: Vegetable Oil 1L | F29: 57600
E30: Yoghurt | F30: 33000
E31: Grand Total | F31: 1013900
N33: Row Labels | O33: Sum of Sum of Column7
N34: Ibadan | O34: 293900
N35: Ife | O35: 202100
N36: Lagos | O36: 308500
N37: Osogbo | O37: 209400
N38: Grand Total | O38: 1013900
A98: Count of Column5 | B98: Column Labels
A99: Row Labels | B99: Biscuits | C99: Bottled Water | D99: Bread | E99: Coffee | F99: Eggs (12) | G99: Laundry Detergent | H99: Milk 1L | I99: Potato Chips | J99: Product | K99: Rice 5kg | L99: Soft Drink | M99: Vegetable Oil 1L | N99: Yoghurt | O99: Grand Total
A100: City | J100: 1 | O100: 1
...

Sheet Pivot Analysis
D1: Pivot Analysis
A2: Revenue by Product | E2: Revenue by City
A3: Row Labels | B3: Sum of Column7 | E3: Row Labels | F3: Sum of Column7
A4: Bottled Water | B4: 9000 | E4: Ife | F4: 202100
A5: Potato Chips | B5: 30600 | E5: Osogbo | F5: 209400
A6: Milk 1L | B6: 30800 | E6: Ibadan | F6: 293900
A7: Yoghurt | B7: 33000 | E7: Lagos | F7: 308500
A8: Soft Drink | B8: 35000 | E8: Grand Total | F8: 1013900
A9: Biscuits | B9: 40800
A10: Bread | B10: 57600
A11: Vegetable Oil 1L | B11: 57600
A12: Laundry Detergent | B12: 87400
A13: Eggs (12) | B13: 96600 | E13: Customer Type
A14: Coffee | B14: 229500 | E14: Row Labels | F14: Sum of Column7
A15: Rice 5kg | B15: 306000 | E15: New | F15: 486700
A16: Grand Total | B16: 1013900 | E16: Regular | F16: 527200
E17: Grand Total | F17: 1013900
A22: Revenue by Category | E22: Monthly Revenue
A23: Row Labels | B23: Sum of Column7 | E23: Row Labels | F23: Sum of Column7
A24: Bakery | B24: 57600 | E24: March | F24: 159200
A25: Snacks | B25: 71400 | E25: May | F25: 169900
A26: Household | B26: 87400 | E26: February | F26: 170700
A27: Dairy | B27: 160400 | E27: April | F27: 224500
A28: Beverages | B28: 273500 | E28: January | F28: 289600
A29: Groceries | B29: 363600 | E29: Grand Total | F29: 1013900
A30: Grand Total | B30: 1013900

Sheet Dashboard
F1: FRESHMART SUPERMARKET SALES DASHBOARD

Sheet Insights & Recommendation
A1: Business Insights
A2: Lagos had the most sales.
A3: Cash was the preferred method among customers.
A4: Highest monthly transaction was recorded in January.
A5: April was the second highest revenue month.
A6: The highest revenue product was rice.
A7: Ife city's branch recorded the lowest sales.
A9: Recommendation
A10: Since Lagos generated the most sales, I recommend allocating more stock and marketing resources to sustain the momentum.
A11: Given that cash is the dominant payment method, ensure adequate cash-handling processes are in place.
A12: Since January recorded the highest monthly transactions,prepare inventory and staffing in advance for that period each year to meet demand.
A13: As April is also a strong revenue month,analyze what drives sales that month(promotions,season,etc.)and replicate strategy in other months.
... A15: Awareness about the business should be increased,especially at the ife branch.

Sheet Sheet3

Sheet Sheet2

Sheet Sheet1

Sheet Sheet8
A1: Row Labels | B1: Sum of Sum of Column7
A2: January | B2: 289600
A3: February | B3: 170700
A4: March | B4: 159200
A5: April | B5: 224500 | F5: Row Labels | G5: Sum of Sum of Column7
A6: May | B6: 169900 | F6: Bakery | G6: 57600
A7: Grand Total | B7: 1013900 | F7: Beverages | G7: 273500
F8: Dairy | G8: 160400
F9: Groceries | G9: 363600
F10: Household | G10: 87400
F11: Snacks | G11: 71400
F12: Grand Total | G12: 1013900

Sheet Sheet9
A1: PRODUCT
A2: ='Pivot Analysis'!$A3 -> Row Labels
A3: ='Pivot Analysis'!$A4 -> Bottled Water | B3: ='Pivot Analysis'!$B4 -> 9000 | D3: =SUMIFS('Cleaned Data'!E:E,'Cleaned Data'!C:C,Sheet9!$A3) -> 18
A4: ='Pivot Analysis'!$A5 -> Potato Chips | B4: ='Pivot Analysis'!$B5 -> 30600 | D4: =SUMIFS('Cleaned Data'!E:E,'Cleaned Data'!C:C,Sheet9!$A4) -> 17
A5: ='Pivot Analysis'!$A6 -> Milk 1L | B5: ='Pivot Analysis'!$B6 -> 30800 | D5: =SUMIFS('Cleaned Data'!E:E,'Cleaned Data'!C:C,Sheet9!$A5) -> 11
A6: ='Pivot Analysis'!$A7 -> Yoghurt | B6: ='Pivot Analysis'!$B7 -> 33000 | D6: =SUMIFS('Cleaned Data'!E:E,'Cleaned Data'!C:C,Sheet9!$A6) -> 22
A7: ='Pivot Analysis'!$A8 -> Soft Drink | B7: ='Pivot Analysis'!$B8 -> 35000 | D7: =SUMIFS('Cleaned Data'!E:E,'Cleaned Data'!C:C,Sheet9!$A7) -> 35
A8: ='Pivot Analysis'!$A9 -> Biscuits | B8: ='Pivot Analysis'!$B9 -> 40800 | D8: =SUMIFS('Cleaned Data'!E:E,'Cleaned Data'!C:C,Sheet9!$A8) -> 34
A9: ='Pivot Analysis'!$A10 -> Bread | B9: ='Pivot Analysis'!$B10 -> 57600 | D9: =SUMIFS('Cleaned Data'!E:E,'Cleaned Data'!C:C,Sheet9!$A9) -> 32
A10: ='Pivot Analysis'!$A11 -> Vegetable Oil 1L | B10: ='Pivot Analysis'!$B11 -> 57600 | D10: =SUMIFS('Cleaned Data'!E:E,'Cleaned Data'!C:C,Sheet9!$A10) -> 18
A11: ='Pivot Analysis'!$A12 -> Laundry Detergent | B11: ='Pivot Analysis'!$B12 -> 87400 | D11: =SUMIFS('Cleaned Data'!E:E,'Cleaned Data'!C:C,Sheet9!$A11) -> 23
A12: ='Pivot Analysis'!$A13 -> Eggs (12) | B12: ='Pivot Analysis'!$B13 -> 96600 | D12: =SUMIFS('Cleaned Data'!E:E,'Cleaned Data'!C:C,Sheet9!$A12) -> 23
A13: ='Pivot Analysis'!$A14 -> Coffee | B13: ='Pivot Analysis'!$B14 -> 229500 | D13: =SUMIFS('Cleaned Data'!E:E,'Cleaned Data'!C:C,Sheet9!$A13) -> 51
A14: ='Pivot Analysis'!$A15 -> Rice 5kg | B14: ='Pivot Analysis'!$B15 -> 306000 | D14: =SUMIFS('Cleaned Data'!E:E,'Cleaned Data'!C:C,Sheet9!$A14) -> 36
A15: ='Pivot Analysis'!$A16 -> Grand Total
